2023-01-24 19:47:23,562 - instabot version: 0.117.0 (bot) - INFO - Instabot version: 0.117.0 Started
2023-01-24 19:47:23,563 - instabot version: 0.117.0 (bot) - DEBUG - Bot imported from C:\Users\Lenovo\marketautomation\venv\Lib\site-packages\instabot\bot\bot.py
2023-01-24 19:47:23,564 - instabot version: 0.117.0 (api_login) - DEBUG - Loading cookies
2023-01-24 19:47:36,024 - instabot version: 0.117.0 (bot) - INFO - Instabot version: 0.117.0 Started
2023-01-24 19:47:36,025 - instabot version: 0.117.0 (bot) - DEBUG - Bot imported from C:\Users\Lenovo\marketautomation\venv\Lib\site-packages\instabot\bot\bot.py
2023-01-24 19:47:36,026 - instabot version: 0.117.0 (api_login) - INFO - Not yet logged in starting: PRE-LOGIN FLOW!
2023-01-24 19:47:36,507 - instabot version: 0.117.0 (api) - DEBUG - POST to endpoint: accounts/get_prefill_candidates/ returned response: <Response [429]>
2023-01-24 19:47:36,507 - instabot version: 0.117.0 (api) - DEBUG - Responsecode indicates error; response content: b'{"message":"Please wait a few minutes before you try again.","status":"fail"}'
2023-01-24 19:47:36,517 - instabot version: 0.117.0 (api) - ERROR - Request returns 429 error!
2023-01-24 19:47:36,523 - instabot version: 0.117.0 (api) - WARNING - That means 'too many requests'. I'll go to sleep for 5 minutes.
2023-01-24 22:33:59,948 - instabot version: 0.117.0 (api) - WARNING - HTTPSConnectionPool(host='i.instagram.com', port=443): Max retries exceeded with url: /api/v1/accounts/get_prefill_candidates/ (Caused by NewConnectionError('<urllib3.connection.HTTPSConnection object at 0x00000175E88C77D0>: Failed to establish a new connection: [Errno 11001] getaddrinfo failed'))
2023-01-24 22:33:59,997 - instabot version: 0.117.0 (api) - WARNING - HTTPSConnectionPool(host='i.instagram.com', port=443): Max retries exceeded with url: /api/v1/qe/sync/ (Caused by NewConnectionError('<urllib3.connection.HTTPSConnection object at 0x00000175E88CD650>: Failed to establish a new connection: [Errno 11001] getaddrinfo failed'))
2023-01-24 22:34:00,033 - instabot version: 0.117.0 (api) - WARNING - HTTPSConnectionPool(host='i.instagram.com', port=443): Max retries exceeded with url: /api/v1/launcher/sync/ (Caused by NewConnectionError('<urllib3.connection.HTTPSConnection object at 0x00000175E88CE850>: Failed to establish a new connection: [Errno 11001] getaddrinfo failed'))
2023-01-24 22:34:00,062 - instabot version: 0.117.0 (api) - WARNING - HTTPSConnectionPool(host='i.instagram.com', port=443): Max retries exceeded with url: /api/v1/accounts/contact_point_prefill/ (Caused by NewConnectionError('<urllib3.connection.HTTPSConnection object at 0x00000175E88CE690>: Failed to establish a new connection: [Errno 11001] getaddrinfo failed'))
